{
    "checksum": "cbf815998a9080d06744f37d1dd12d549b238676133ad0ce3b2326e810c9678b",
    "file": "smtpd.py",
    "mime": {
        "encoding": "us-ascii",
        "type": "text/x-python"
    },
    "number_of_duplicates": 1,
    "package": "aiosmtplib",
    "path": "aiosmtplib/1.1.4-1/.pc/0001-tests-smtpd-Return-an-error-when-auth-is-called-with.patch/tests/smtpd.py",
    "pkg_infos": {
        "area": "main",
        "copyright": true,
        "ctags_count": 0,
        "license": "/copyright/license/aiosmtplib/1.1.4-1/",
        "metric": {
            "size": 488
        },
        "pts_link": "https://tracker.debian.org/pkg/aiosmtplib",
        "sloc": [
            [
                "python",
                4959
            ],
            [
                "makefile",
                22
            ],
            [
                "sh",
                6
            ]
        ],
        "suites": [
            "sid"
        ],
        "vcs_browser": "https://salsa.debian.org/python-team/packages/aiosmtplib",
        "vcs_type": "git"
    },
    "raw_url": "/data/main/a/aiosmtplib/1.1.4-1/.pc/0001-tests-smtpd-Return-an-error-when-auth-is-called-with.patch/tests/smtpd.py",
    "stat": {
        "perms": "rw-r--r--",
        "size": 6369,
        "symlink_dest": null,
        "type": "-"
    },
    "text_file": true,
    "type": "file",
    "version": "1.1.4-1"
}