{
    "checksum": "59254b1809fb765f6cdb073d52ca8b1e3b40be5ad47dd9be6b03e8d4460da4ff",
    "file": "_converters.py",
    "mime": {
        "encoding": "us-ascii",
        "type": "text/x-python"
    },
    "number_of_duplicates": 2,
    "package": "azure-kusto-python",
    "path": "azure-kusto-python/1.0.3-1/.pc/0001-Restore-compatibility-with-dateutil-2.7.x.patch/azure-kusto-data/azure/kusto/data/_converters.py",
    "pkg_infos": {
        "area": "main",
        "copyright": true,
        "ctags_count": 0,
        "license": "/copyright/license/azure-kusto-python/1.0.3-1/",
        "metric": {
            "size": 616
        },
        "pts_link": "https://tracker.debian.org/pkg/azure-kusto-python",
        "sloc": [
            [
                "python",
                3871
            ],
            [
                "sh",
                10
            ],
            [
                "makefile",
                6
            ]
        ],
        "suites": [
            "bookworm",
            "bullseye",
            "sid"
        ],
        "vcs_browser": "https://salsa.debian.org/python-team/packages/azure-kusto-python",
        "vcs_type": "git"
    },
    "raw_url": "/data/main/a/azure-kusto-python/1.0.3-1/.pc/0001-Restore-compatibility-with-dateutil-2.7.x.patch/azure-kusto-data/azure/kusto/data/_converters.py",
    "stat": {
        "perms": "rw-r--r--",
        "size": 1023,
        "symlink_dest": null,
        "type": "-"
    },
    "text_file": true,
    "type": "file",
    "version": "1.0.3-1"
}