{
    "checksum": "3f26c6c2fcfc1b2327a87de5165d6016bc9ed1323491f5e8652efaa4badbbc6e",
    "file": "0001-tests-smtpd-Return-an-error-when-auth-is-called-with.patch",
    "mime": {
        "encoding": "us-ascii",
        "type": "text/x-diff"
    },
    "number_of_duplicates": 1,
    "package": "aiosmtplib",
    "path": "aiosmtplib/1.1.4-1/debian/patches/0001-tests-smtpd-Return-an-error-when-auth-is-called-with.patch",
    "pkg_infos": {
        "area": "main",
        "copyright": true,
        "ctags_count": 0,
        "license": "/copyright/license/aiosmtplib/1.1.4-1/",
        "metric": {
            "size": 488
        },
        "pts_link": "https://tracker.debian.org/pkg/aiosmtplib",
        "sloc": [
            [
                "python",
                4959
            ],
            [
                "makefile",
                22
            ],
            [
                "sh",
                6
            ]
        ],
        "suites": [
            "sid"
        ],
        "vcs_browser": "https://salsa.debian.org/python-team/packages/aiosmtplib",
        "vcs_type": "git"
    },
    "raw_url": "/data/main/a/aiosmtplib/1.1.4-1/debian/patches/0001-tests-smtpd-Return-an-error-when-auth-is-called-with.patch",
    "stat": {
        "perms": "rw-r--r--",
        "size": 714,
        "symlink_dest": null,
        "type": "-"
    },
    "text_file": true,
    "type": "file",
    "version": "1.1.4-1"
}