{
    "checksum": "57635c50e4cfce510ace7f02b307e565c2ff73eb44fd8d609ed88a0f094983c6",
    "file": "0001-Restore-compatibility-with-dateutil-2.7.x.patch",
    "mime": {
        "encoding": "us-ascii",
        "type": "text/x-diff"
    },
    "number_of_duplicates": 1,
    "package": "azure-kusto-python",
    "path": "azure-kusto-python/1.0.3-1/debian/patches/0001-Restore-compatibility-with-dateutil-2.7.x.patch",
    "pkg_infos": {
        "area": "main",
        "copyright": true,
        "ctags_count": 0,
        "license": "/copyright/license/azure-kusto-python/1.0.3-1/",
        "metric": {
            "size": 616
        },
        "pts_link": "https://tracker.debian.org/pkg/azure-kusto-python",
        "sloc": [
            [
                "python",
                3871
            ],
            [
                "sh",
                10
            ],
            [
                "makefile",
                6
            ]
        ],
        "suites": [
            "bookworm",
            "bullseye",
            "sid"
        ],
        "vcs_browser": "https://salsa.debian.org/python-team/packages/azure-kusto-python",
        "vcs_type": "git"
    },
    "raw_url": "/data/main/a/azure-kusto-python/1.0.3-1/debian/patches/0001-Restore-compatibility-with-dateutil-2.7.x.patch",
    "stat": {
        "perms": "rw-r--r--",
        "size": 1478,
        "symlink_dest": null,
        "type": "-"
    },
    "text_file": true,
    "type": "file",
    "version": "1.0.3-1"
}